[2025-02-22 04:30:58 -0500] [26324] [INFO] Starting gunicorn 23.0.0
[2025-02-22 04:30:58 -0500] [26324] [INFO] Listening at: http://0.0.0.0:8080 (26324)
[2025-02-22 04:30:58 -0500] [26324] [INFO] Using worker: sync
[2025-02-22 04:30:58 -0500] [26325] [INFO] Booting worker with pid: 26325
[2025-02-22 04:30:58 -0500] [26327] [INFO] Booting worker with pid: 26327
[2025-02-22 04:30:58 -0500] [26328] [INFO] Booting worker with pid: 26328
[2025-02-22 04:30:58 -0500] [26329] [INFO] Booting worker with pid: 26329
[2025-02-22 04:31:43 -0500] [26324] [CRITICAL] WORKER TIMEOUT (pid:26325)
[2025-02-22 04:31:43 -0500] [26325] [ERROR] Error handling request (no URI read)
Traceback (most recent call last):
  File "/data/data/com.termux/files/usr/lib/python3.12/site-packages/gunicorn/workers/sync.py", line 133, in handle
    req = next(parser)
          ^^^^^^^^^^^^
  File "/data/data/com.termux/files/usr/lib/python3.12/site-packages/gunicorn/http/parser.py", line 41, in __next__
    self.mesg = self.mesg_class(self.cfg, self.unreader, self.source_addr, self.req_count)
                ^^^^^^^^^^^^^^^^^^^^^^^^^^^^^^^^^^^^^^^^^^^^^^^^^^^^^^^^^^^^^^^^^^^^^^^^^^
  File "/data/data/com.termux/files/usr/lib/python3.12/site-packages/gunicorn/http/message.py", line 259, in __init__
    super().__init__(cfg, unreader, peer_addr)
  File "/data/data/com.termux/files/usr/lib/python3.12/site-packages/gunicorn/http/message.py", line 60, in __init__
    unused = self.parse(self.unreader)
             ^^^^^^^^^^^^^^^^^^^^^^^^^
  File "/data/data/com.termux/files/usr/lib/python3.12/site-packages/gunicorn/http/message.py", line 271, in parse
    self.get_data(unreader, buf, stop=True)
  File "/data/data/com.termux/files/usr/lib/python3.12/site-packages/gunicorn/http/message.py", line 262, in get_data
    data = unreader.read()
           ^^^^^^^^^^^^^^^
  File "/data/data/com.termux/files/usr/lib/python3.12/site-packages/gunicorn/http/unreader.py", line 36, in read
    d = self.chunk()
        ^^^^^^^^^^^^
  File "/data/data/com.termux/files/usr/lib/python3.12/site-packages/gunicorn/http/unreader.py", line 63, in chunk
    return self.sock.recv(self.mxchunk)
           ^^^^^^^^^^^^^^^^^^^^^^^^^^^^
  File "/data/data/com.termux/files/usr/lib/python3.12/site-packages/gunicorn/workers/base.py", line 204, in handle_abort
    sys.exit(1)
SystemExit: 1
[2025-02-22 04:31:43 -0500] [26325] [INFO] Worker exiting (pid: 26325)
[2025-02-22 04:31:44 -0500] [27031] [INFO] Booting worker with pid: 27031
[2025-02-22 04:42:41,058] ERROR in app: Exception on /login [POST]
Traceback (most recent call last):
  File "/data/data/com.termux/files/usr/lib/python3.12/site-packages/flask/app.py", line 1511, in wsgi_app
    response = self.full_dispatch_request()
               ^^^^^^^^^^^^^^^^^^^^^^^^^^^^
  File "/data/data/com.termux/files/usr/lib/python3.12/site-packages/flask/app.py", line 919, in full_dispatch_request
    rv = self.handle_user_exception(e)
         ^^^^^^^^^^^^^^^^^^^^^^^^^^^^^
  File "/data/data/com.termux/files/usr/lib/python3.12/site-packages/flask_cors/extension.py", line 194, in wrapped_function
    return cors_after_request(app.make_response(f(*args, **kwargs)))
                                                ^^^^^^^^^^^^^^^^^^
  File "/data/data/com.termux/files/usr/lib/python3.12/site-packages/flask/app.py", line 917, in full_dispatch_request
    rv = self.dispatch_request()
         ^^^^^^^^^^^^^^^^^^^^^^^
  File "/data/data/com.termux/files/usr/lib/python3.12/site-packages/flask/app.py", line 902, in dispatch_request
    return self.ensure_sync(self.view_functions[rule.endpoint])(**view_args)  # type: ignore[no-any-return]
           ^^^^^^^^^^^^^^^^^^^^^^^^^^^^^^^^^^^^^^^^^^^^^^^^^^^^^^^^^^^^^^^^^
  File "/data/data/com.termux/files/home/GhostSpoof/app.py", line 42, in login
    user = User.query.filter_by(email=data['email'], password=data['password']).first()
                                      ~~~~^^^^^^^^^
KeyError: 'email'
[2025-02-22 04:48:46 -0500] [26324] [INFO] Handling signal: term
[2025-02-22 04:48:46 -0500] [26328] [INFO] Worker exiting (pid: 26328)
[2025-02-22 04:48:46 -0500] [26327] [INFO] Worker exiting (pid: 26327)
[2025-02-22 04:48:46 -0500] [26329] [INFO] Worker exiting (pid: 26329)
[2025-02-22 04:48:46 -0500] [27031] [INFO] Worker exiting (pid: 27031)
[2025-02-22 04:48:47 -0500] [26324] [INFO] Shutting down: Master
[2025-02-22 04:48:58 -0500] [7128] [INFO] Starting gunicorn 23.0.0
[2025-02-22 04:48:58 -0500] [7128] [INFO] Listening at: http://0.0.0.0:8080 (7128)
[2025-02-22 04:48:58 -0500] [7128] [INFO] Using worker: sync
[2025-02-22 04:48:58 -0500] [7131] [INFO] Booting worker with pid: 7131
[2025-02-22 04:48:58 -0500] [7132] [INFO] Booting worker with pid: 7132
[2025-02-22 04:48:58 -0500] [7133] [INFO] Booting worker with pid: 7133
[2025-02-22 04:48:58 -0500] [7134] [INFO] Booting worker with pid: 7134
[2025-02-22 05:08:56 -0500] [7131] [INFO] Worker exiting (pid: 7131)
[2025-02-22 05:08:56 -0500] [7128] [INFO] Handling signal: term
[2025-02-22 05:08:56 -0500] [7132] [INFO] Worker exiting (pid: 7132)
[2025-02-22 05:08:56 -0500] [7134] [INFO] Worker exiting (pid: 7134)
[2025-02-22 05:08:56 -0500] [7133] [INFO] Worker exiting (pid: 7133)
[2025-02-22 05:08:57 -0500] [7128] [INFO] Shutting down: Master
[2025-02-22 05:10:01 -0500] [19743] [INFO] Starting gunicorn 23.0.0
[2025-02-22 05:10:01 -0500] [19743] [INFO] Listening at: http://0.0.0.0:8080 (19743)
[2025-02-22 05:10:01 -0500] [19743] [INFO] Using worker: sync
[2025-02-22 05:10:01 -0500] [19745] [INFO] Booting worker with pid: 19745
[2025-02-22 05:10:01 -0500] [19746] [INFO] Booting worker with pid: 19746
[2025-02-22 05:10:01 -0500] [19747] [INFO] Booting worker with pid: 19747
[2025-02-22 05:10:01 -0500] [19748] [INFO] Booting worker with pid: 19748
[2025-02-22 05:10:03 -0500] [19746] [ERROR] Exception in worker process
Traceback (most recent call last):
  File "/data/data/com.termux/files/usr/lib/python3.12/site-packages/gunicorn/arbiter.py", line 608, in spawn_worker
    worker.init_process()
  File "/data/data/com.termux/files/usr/lib/python3.12/site-packages/gunicorn/workers/base.py", line 135, in init_process
    self.load_wsgi()
  File "/data/data/com.termux/files/usr/lib/python3.12/site-packages/gunicorn/workers/base.py", line 147, in load_wsgi
    self.wsgi = self.app.wsgi()
                ^^^^^^^^^^^^^^^
  File "/data/data/com.termux/files/usr/lib/python3.12/site-packages/gunicorn/app/base.py", line 66, in wsgi
    self.callable = self.load()
                    ^^^^^^^^^^^
  File "/data/data/com.termux/files/usr/lib/python3.12/site-packages/gunicorn/app/wsgiapp.py", line 57, in load
    return self.load_wsgiapp()
           ^^^^^^^^^^^^^^^^^^^
  File "/data/data/com.termux/files/usr/lib/python3.12/site-packages/gunicorn/app/wsgiapp.py", line 47, in load_wsgiapp
    return util.import_app(self.app_uri)
           ^^^^^^^^^^^^^^^^^^^^^^^^^^^^^
  File "/data/data/com.termux/files/usr/lib/python3.12/site-packages/gunicorn/util.py", line 370, in import_app
    mod = importlib.import_module(module)
          ^^^^^^^^^^^^^^^^^^^^^^^^^^^^^^^
  File "/data/data/com.termux/files/usr/lib/python3.12/importlib/__init__.py", line 90, in import_module
    return _bootstrap._gcd_import(name[level:], package, level)
           ^^^^^^^^^^^^^^^^^^^^^^^^^^^^^^^^^^^^^^^^^^^^^^^^^^^^
  File "<frozen importlib._bootstrap>", line 1387, in _gcd_import
  File "<frozen importlib._bootstrap>", line 1360, in _find_and_load
  File "<frozen importlib._bootstrap>", line 1331, in _find_and_load_unlocked
  File "<frozen importlib._bootstrap>", line 935, in _load_unlocked
  File "<frozen importlib._bootstrap_external>", line 999, in exec_module
  File "<frozen importlib._bootstrap>", line 488, in _call_with_frames_removed
  File "/data/data/com.termux/files/home/GhostSpoof/app.py", line 3, in <module>
    from flask_bcrypt import Bcrypt
ModuleNotFoundError: No module named 'flask_bcrypt'
[2025-02-22 05:10:03 -0500] [19748] [ERROR] Exception in worker process
Traceback (most recent call last):
  File "/data/data/com.termux/files/usr/lib/python3.12/site-packages/gunicorn/arbiter.py", line 608, in spawn_worker
    worker.init_process()
  File "/data/data/com.termux/files/usr/lib/python3.12/site-packages/gunicorn/workers/base.py", line 135, in init_process
    self.load_wsgi()
  File "/data/data/com.termux/files/usr/lib/python3.12/site-packages/gunicorn/workers/base.py", line 147, in load_wsgi
    self.wsgi = self.app.wsgi()
                ^^^^^^^^^^^^^^^
  File "/data/data/com.termux/files/usr/lib/python3.12/site-packages/gunicorn/app/base.py", line 66, in wsgi
    self.callable = self.load()
                    ^^^^^^^^^^^
  File "/data/data/com.termux/files/usr/lib/python3.12/site-packages/gunicorn/app/wsgiapp.py", line 57, in load
    return self.load_wsgiapp()
           ^^^^^^^^^^^^^^^^^^^
  File "/data/data/com.termux/files/usr/lib/python3.12/site-packages/gunicorn/app/wsgiapp.py", line 47, in load_wsgiapp
    return util.import_app(self.app_uri)
           ^^^^^^^^^^^^^^^^^^^^^^^^^^^^^
  File "/data/data/com.termux/files/usr/lib/python3.12/site-packages/gunicorn/util.py", line 370, in import_app
    mod = importlib.import_module(module)
          ^^^^^^^^^^^^^^^^^^^^^^^^^^^^^^^
  File "/data/data/com.termux/files/usr/lib/python3.12/importlib/__init__.py", line 90, in import_module
    return _bootstrap._gcd_import(name[level:], package, level)
           ^^^^^^^^^^^^^^^^^^^^^^^^^^^^^^^^^^^^^^^^^^^^^^^^^^^^
  File "<frozen importlib._bootstrap>", line 1387, in _gcd_import
  File "<frozen importlib._bootstrap>", line 1360, in _find_and_load
  File "<frozen importlib._bootstrap>", line 1331, in _find_and_load_unlocked
  File "<frozen importlib._bootstrap>", line 935, in _load_unlocked
  File "<frozen importlib._bootstrap_external>", line 999, in exec_module
  File "<frozen importlib._bootstrap>", line 488, in _call_with_frames_removed
  File "/data/data/com.termux/files/home/GhostSpoof/app.py", line 3, in <module>
    from flask_bcrypt import Bcrypt
ModuleNotFoundError: No module named 'flask_bcrypt'
[2025-02-22 05:10:03 -0500] [19745] [ERROR] Exception in worker process
Traceback (most recent call last):
  File "/data/data/com.termux/files/usr/lib/python3.12/site-packages/gunicorn/arbiter.py", line 608, in spawn_worker
    worker.init_process()
  File "/data/data/com.termux/files/usr/lib/python3.12/site-packages/gunicorn/workers/base.py", line 135, in init_process
    self.load_wsgi()
  File "/data/data/com.termux/files/usr/lib/python3.12/site-packages/gunicorn/workers/base.py", line 147, in load_wsgi
    self.wsgi = self.app.wsgi()
                ^^^^^^^^^^^^^^^
  File "/data/data/com.termux/files/usr/lib/python3.12/site-packages/gunicorn/app/base.py", line 66, in wsgi
    self.callable = self.load()
                    ^^^^^^^^^^^
  File "/data/data/com.termux/files/usr/lib/python3.12/site-packages/gunicorn/app/wsgiapp.py", line 57, in load
    return self.load_wsgiapp()
           ^^^^^^^^^^^^^^^^^^^
  File "/data/data/com.termux/files/usr/lib/python3.12/site-packages/gunicorn/app/wsgiapp.py", line 47, in load_wsgiapp
    return util.import_app(self.app_uri)
           ^^^^^^^^^^^^^^^^^^^^^^^^^^^^^
  File "/data/data/com.termux/files/usr/lib/python3.12/site-packages/gunicorn/util.py", line 370, in import_app
    mod = importlib.import_module(module)
          ^^^^^^^^^^^^^^^^^^^^^^^^^^^^^^^
  File "/data/data/com.termux/files/usr/lib/python3.12/importlib/__init__.py", line 90, in import_module
    return _bootstrap._gcd_import(name[level:], package, level)
           ^^^^^^^^^^^^^^^^^^^^^^^^^^^^^^^^^^^^^^^^^^^^^^^^^^^^
  File "<frozen importlib._bootstrap>", line 1387, in _gcd_import
  File "<frozen importlib._bootstrap>", line 1360, in _find_and_load
  File "<frozen importlib._bootstrap>", line 1331, in _find_and_load_unlocked
  File "<frozen importlib._bootstrap>", line 935, in _load_unlocked
  File "<frozen importlib._bootstrap_external>", line 999, in exec_module
  File "<frozen importlib._bootstrap>", line 488, in _call_with_frames_removed
  File "/data/data/com.termux/files/home/GhostSpoof/app.py", line 3, in <module>
    from flask_bcrypt import Bcrypt
ModuleNotFoundError: No module named 'flask_bcrypt'
[2025-02-22 05:10:03 -0500] [19747] [ERROR] Exception in worker process
Traceback (most recent call last):
  File "/data/data/com.termux/files/usr/lib/python3.12/site-packages/gunicorn/arbiter.py", line 608, in spawn_worker
    worker.init_process()
  File "/data/data/com.termux/files/usr/lib/python3.12/site-packages/gunicorn/workers/base.py", line 135, in init_process
    self.load_wsgi()
  File "/data/data/com.termux/files/usr/lib/python3.12/site-packages/gunicorn/workers/base.py", line 147, in load_wsgi
    self.wsgi = self.app.wsgi()
                ^^^^^^^^^^^^^^^
  File "/data/data/com.termux/files/usr/lib/python3.12/site-packages/gunicorn/app/base.py", line 66, in wsgi
    self.callable = self.load()
                    ^^^^^^^^^^^
  File "/data/data/com.termux/files/usr/lib/python3.12/site-packages/gunicorn/app/wsgiapp.py", line 57, in load
    return self.load_wsgiapp()
           ^^^^^^^^^^^^^^^^^^^
  File "/data/data/com.termux/files/usr/lib/python3.12/site-packages/gunicorn/app/wsgiapp.py", line 47, in load_wsgiapp
    return util.import_app(self.app_uri)
           ^^^^^^^^^^^^^^^^^^^^^^^^^^^^^
  File "/data/data/com.termux/files/usr/lib/python3.12/site-packages/gunicorn/util.py", line 370, in import_app
    mod = importlib.import_module(module)
          ^^^^^^^^^^^^^^^^^^^^^^^^^^^^^^^
  File "/data/data/com.termux/files/usr/lib/python3.12/importlib/__init__.py", line 90, in import_module
    return _bootstrap._gcd_import(name[level:], package, level)
           ^^^^^^^^^^^^^^^^^^^^^^^^^^^^^^^^^^^^^^^^^^^^^^^^^^^^
  File "<frozen importlib._bootstrap>", line 1387, in _gcd_import
  File "<frozen importlib._bootstrap>", line 1360, in _find_and_load
  File "<frozen importlib._bootstrap>", line 1331, in _find_and_load_unlocked
  File "<frozen importlib._bootstrap>", line 935, in _load_unlocked
  File "<frozen importlib._bootstrap_external>", line 999, in exec_module
  File "<frozen importlib._bootstrap>", line 488, in _call_with_frames_removed
  File "/data/data/com.termux/files/home/GhostSpoof/app.py", line 3, in <module>
    from flask_bcrypt import Bcrypt
ModuleNotFoundError: No module named 'flask_bcrypt'
[2025-02-22 05:10:03 -0500] [19746] [INFO] Worker exiting (pid: 19746)
[2025-02-22 05:10:03 -0500] [19745] [INFO] Worker exiting (pid: 19745)
[2025-02-22 05:10:03 -0500] [19748] [INFO] Worker exiting (pid: 19748)
[2025-02-22 05:10:03 -0500] [19747] [INFO] Worker exiting (pid: 19747)
[2025-02-22 05:10:03 -0500] [19743] [ERROR] Worker (pid:19747) exited with code 3
[2025-02-22 05:10:03 -0500] [19743] [ERROR] Worker (pid:19748) exited with code 3
[2025-02-22 05:10:03 -0500] [19743] [ERROR] Shutting down: Master
[2025-02-22 05:10:03 -0500] [19743] [ERROR] Reason: Worker failed to boot.
